Workbook

Sheet 2025 v. INVENTORY OF BRICKS
A1: Column 1 | B1: Newly Printed | C1: Air Dried | D1: Bricks in the Kiln for firing | E1: Already Fired | F1: Reclaimed (newly Printed) | G1: Reclaimed (Air Dried) | H1: Available Pre-filled Bricks | I1: Deployed | J1: Total Air Dried | K1: Actual Count | L1: Total Fired | M1: Overall Total | N1: Remarks/ Comment | O1: Deficit
A2: 45931 | B2: 10 | C2: 209 | D2: 0 | E2: 193 | J2: =C2+B2-D2-G2 -> 219 | L2: =E2+D2 -> 193 | M2: =L2+J2 -> 412 | O2: =B2-16 -> -6 | P2: =sum(O2:O12) -> -51
A3: 45932 | B3: 19 | C3: =J2 -> 219 | D3: 29 | E3: =L2 -> 193 | J3: =C3+B3-D3-G3 -> 209 | L3: =E3+D3 -> 222 | M3: =L3+J3 -> 431 | O3: =B3-16 -> 3
A4: 45933 | B4: 12 | C4: =J3 -> 209 | D4: 0 | E4: =L3 -> 222 | J4: =C4+B4-D4-G4 -> 221 | L4: =E4+D4 -> 222 | M4: =L4+J4 -> 443 | O4: =B4-16 -> -4
A5: 45936 | B5: 11 | C5: =J4 -> 221 | D5: 29 | E5: =L4 -> 222 | J5: =C5+B5-D5-G5 -> 203 | L5: =E5+D5 -> 251 | M5: =L5+J5 -> 454 | N5: most bricks were over burnt | O5: =B5-16 -> -5
A6: 45937 | B6: 12 | C6: =J5 -> 203 | D6: 0 | E6: =L5 -> 251 | J6: =C6+B6-D6-G6 -> 215 | L6: =E6+D6 -> 251 | M6: =L6+J6 -> 466 | O6: =B6-16 -> -4
A7: 45938 | B7: 20 | C7: =J6 -> 215 | D7: 29 | E7: =L6 -> 251 | J7: =C7+B7-D7-G7 -> 206 | L7: =E7+D7 -> 280 | M7: =L7+J7 -> 486 | O7: =B7-16 -> 4
A8: 45939 | B8: 0 | C8: =J7 -> 206 | D8: 0 | E8: =L7 -> 280 | J8: =C8+B8-D8-G8 -> 206 | L8: =E8+D8 -> 280 | M8: =L8+J8 -> 486 | O8: =B8-16 -> -16
A9: 45950 | B9: 14 | C9: =J8 -> 206 | D9: 0 | E9: =L8 -> 280 | J9: =C9+B9-D9-G9 -> 220 | L9: =E9+D9 -> 280 | M9: =L9+J9 -> 500 | O9: =B9-16 -> -2
A10: 45951 | B10: 16 | C10: =J9 -> 220 | D10: 29 | E10: =L9 -> 280 | J10: =C10+B10-D10-G10 -> 207 | L10: =E10+D10 -> 309 | M10: =L10+J10 -> 516 | O10: =B10-16 -> 0
A11: 45952 | B11: 7 | C11: =J10 -> 207 | D11: 0 | E11: =L10 -> 309 | J11: =C11+B11-D11-G11 -> 214 | L11: =E11+D11 -> 309 | M11: =L11+J11 -> 523 | O11: =B11-16 -> -9
A12: 45953 | B12: 4 | C12: =J11 -> 214 | D12: 29 | E12: =L11 -> 309 | J12: =C12+B12-D12-G12 -> 189 | L12: =E12+D12 -> 338 | M12: =L12+J12 -> 527 | N12: 1 brick was recycled due to crack at the base | O12: =B12-16 -> -12
A13: 45964 | C13: 181 | D13: 0 | E13: 99 | J13: =C13+B13-D13-G13 -> 181 | L13: 99 | M13: =L13+J13 -> 280 | N13: 240 bricks were deployed on oct 27 & 28. 61 bricks can be used only, 5 bricks were test sample, 21 bricks were old model, 5 were tested and fully damaged, 7 were used for display and 1 brick was not returned by Mauro
A14: 45964 | B14: 14 | C14: =J13 -> 181 | D14: 0 | E14: 61 | F14: 2 | G14: 0 | J14: =C14+B14-D14-G14-F14 -> 193 | L14: =E14+D14 -> 61 | M14: =L14+J14 -> 254 | N14: reclaimed printed bricks was due to pin problem | O14: =B14-16 -> -2 | P14: =sum(O14:O18) -> -36
A15: 45965 | B15: 8 | C15: =J14 -> 193 | D15: 29 | E15: =L14 -> 61 | F15: 0 | G15: 0 | J15: =C15+B15-D15-G15-F15 -> 172 | L15: =E15+D15 -> 90 | M15: =L15+J15 -> 262 | O15: =B15-16 -> -8
A16: 45966 | B16: 8 | C16: =J15 -> 172 | D16: 0 | E16: =L15 -> 90 | F16: 0 | G16: 0 | J16: =C16+B16-D16-G16-F16 -> 180 | L16: =E16+D16 -> 90 | M16: =L16+J16 -> 270 | O16: =B16-16 -> -8
A17: 45967 | B17: 10 | C17: =J16 -> 180 | D17: 29 | E17: =L16 -> 90 | F17: 0 | G17: 1 | J17: =C17+B17-D17-G17-F17 -> 160 | L17: =E17+D17 -> 119 | M17: =L17+J17 -> 279 | N17: reclaimed air dried brick was due to uneven flooring | O17: =B17-16 -> -6
A18: 45968 | B18: 4 | C18: =J17 -> 160 | D18: 0 | E18: =L17 -> 119 | F18: 0 | G18: 25 | J18: =C18+B18-D18-G18-F18 -> 139 | L18: =E18+D18 -> 119 | M18: =L18+J18 -> 258 | N18: the 25 old model were washed by rain. 16 old model were not included in the counting. | O18: =B18-16 -> -12
A19: 45971 | B19: 15 | C19: =J18 -> 139 | D19: 0 | E19: =L18 -> 119 | F19: 0 | G19: 0 | J19: =C19+B19-D19-G19-F19 -> 154 | L19: =E19+D19 -> 119 | M19: =L19+J19 -> 273 | O19: =B19-16 -> -1 | P19: =sum(O19:O23) -> -13
A20: 45972 | B20: 10 | C20: =J19 -> 154 | D20: 0 | E20: =L18 -> 119 | F20: 0 | G20: 0 | J20: =C20+B20-D20-G20-F20 -> 164 | L20: =E20+D20 -> 119 | M20: =L20+J20 -> 283 | O20: =B20-16 -> -6
A21: 45973 | B21: 10 | C21: =J20 -> 164 | D21: 0 | E21: =L20 -> 119 | F21: 0 | G21: 0 | J21: =C21+B21-D21-G21-F21 -> 174 | L21: =E21+D21 -> 119 | M21: =L21+J21 -> 293 | O21: =B21-16 -> -6
A22: 45974 | B22: 16 | C22: =J21 -> 174 | D22: 0 | E22: =L21 -> 119 | F22: 0 | G22: 0 | J22: =C22+B22-D22-G22-F22 -> 190 | L22: =E22+D22 -> 119 | M22: =L22+J22 -> 309 | O22: =B22-16 -> 0
A23: 45975 | B23: 16 | C23: =J22 -> 190 | D23: 0 | E23: =L22 -> 119 | F23: 0 | G23: 0 | J23: =C23+B23-D23-G23-F23 -> 206 | K23: 190 | L23: =E23+D23 -> 119 | M23: =L23+J23 -> 325 | O23: =B23-16 -> 0
A24: 45978 | B24: 14 | C24: =J23 -> 206 | D24: 0 | E24: =L23 -> 119 | F24: 0 | G24: 0 | J24: =C24+B24-D24-G24-F24 -> 220 | L24: =E24+D24 -> 119 | M24: =L24+J24 -> 339 | O24: =B24-16 -> -2 | P24: =SUM(O24:O28) -> -34
A25: 45979 | B25: 2 | C25: =J24 -> 220 | D25: 0 | E25: =L24 -> 119 | F25: 0 | G25: 1 | J25: =C25+B25-D25-G25-F25 -> 221 | L25: =E25+D25 -> 119 | M25: =L25+J25 -> 340 | O25: =B25-16 -> -14
A26: 45980 | B26: 11 | C26: =J25 -> 221 | D26: 0 | E26: =L25 -> 119 | F26: 0 | G26: 0 | J26: =C26+B26-D26-G26-F26 -> 232 | L26: =E26+D26 -> 119 | M26: =L26+J26 -> 351 | O26: =B26-16 -> -5
A27: 45981 | B27: 8 | C27: =J26 -> 232 | D27: 0 | E27: =L26 -> 119 | F27: 0 | G27: 0 | J27: =C27+B27-D27-G27-F27 -> 240 | L27: =E27+D27 -> 119 | M27: =L27+J27 -> 359 | O27: =B27-16 -> -8
A28: 45982 | B28: 11 | C28: =J27 -> 240 | D28: 29 | E28: =L27 -> 119 | F28: 0 | G28: 0 | J28: =C28+B28-D28-G28-F28 -> 222 | L28: =E28+D28 -> 148 | M28: =L28+J28 -> 370 | O28: =B28-16 -> -5
A29: 45985 | B29: 16 | C29: =J28 -> 222 | D29: 0 | E29: =L28 -> 148 | F29: 0 | G29: 2 | H29: 65 | I29: 61 | J29: =C29+B29-D29-G29-F29 -> 236 | L29: =148-I29 -> 87 | M29: =L29+J29 -> 323 | N29: 65 bricks were prepared for deployment | O29: =B29-16 -> 0 | P29: =SUM(O29:O33) -> -22
A30: 45986 | B30: 4 | C30: =J29 -> 236 | D30: 29 | E30: =L29 -> 87 | F30: 0 | G30: 1 | H30: =H29-I29 -> 4 | I30: 0 | J30: =C30+B30-D30-G30-F30 -> 210 | L30: =E30+D30 -> 116 | M30: =L30+J30 -> 326 | N30: fired bricks with 2 minor cracks | O30: =B30-16 -> -12
A31: 45987 | B31: 12 | C31: =J30 -> 210 | D31: 0 | E31: =L30 -> 116 | F31: 0 | G31: 5 | H31: =H30-I30 -> 4 | I31: 0 | J31: =C31+B31-D31-G31-F31 -> 217 | L31: =E31+D31 -> 116 | M31: =L31+J31 -> 333 | O31: =B31-16 -> -4
A32: 45988 | B32: 12 | C32: =J31 -> 217 | D32: 29 | E32: =L31 -> 116 | F32: 0 | G32: 0 | H32: =H31-I31 -> 4 | I32: 0 | J32: =C32+B32-D32-G32-F32 -> 200 | L32: =E32+D32 -> 145 | M32: =L32+J32 -> 345 | N32: fired bricks with 1 major crack. | O32: =B32-16 -> -4
A33: 45989 | B33: 14 | C33: =J32 -> 200 | D33: 0 | E33: =L32 -> 145 | F33: 0 | G33: 0 | H33: =H32-I32 -> 4 | I33: 0 | J33: =C33+B33-D33-G33-F33 -> 214 | L33: =E33+D33 -> 145 | M33: =L33+J33 -> 359 | O33: =B33-16 -> -2
A34: 45992 | B34: 10 | C34: =J33 -> 214 | D34: 0 | E34: =L33 -> 145 | F34: 0 | G34: 0 | H34: =H33-I33 -> 4 | I34: 0 | J34: =C34+B34-D34-G34-F34 -> 224 | L34: =E34+D34 -> 145 | M34: =L34+J34 -> 369 | O34: =B34-16 -> -6
A35: 45993 | B35: 16 | C35: =J34 -> 224 | D35: 29 | E35: =L34 -> 145 | F35: 0 | G35: 0 | H35: =H34-I34 -> 4 | I35: 0 | J35: =C35+B35-D35-G35-F35 -> 211 | L35: =E35+D35 -> 174 | M35: =L35+J35 -> 385 | N35: 2 bricks with cracks. | O35: =B35-16 -> 0
A36: 45994 | B36: 12 | C36: =J35 -> 211 | D36: 0 | E36: =L35 -> 174 | F36: 0 | G36: 2 | H36: =H35-I35 -> 4 | I36: 0 | J36: =C36+B36-D36-G36-F36 -> 221 | L36: =E36+D36 -> 174 | M36: =L36+J36 -> 395 | O36: =B36-16 -> -4
A37: 45995 | B37: 16 | C37: =J36 -> 221 | D37: 29 | E37: =L36 -> 174 | F37: 0 | G37: 0 | H37: =H36-I36 -> 4 | I37: 0 | J37: =C37+B37-D37-G37-F37 -> 208 | L37: =E37+D37 -> 203 | M37: =L37+J37 -> 411 | O37: =B37-16 -> 0
A38: 45996 | B38: 8 | C38: =J37 -> 208 | D38: 0 | E38: =L37 -> 203 | F38: 0 | G38: 0 | H38: =H37-I37 -> 4 | I38: 0 | J38: =C38+B38-D38-G38-F38 -> 216 | L38: =E38+D38 -> 203 | M38: =L38+J38 -> 419 | N38: 3 bricks with cracks. | O38: =B38-16 -> -8
A39: 46000 | B39: 16 | C39: =J38 -> 216 | D39: 0 | E39: =L38 -> 203 | F39: 0 | G39: 5 | H39: =H38-I38 -> 4 | I39: 0 | J39: =C39+B39-D39-G39-F39 -> 227 | L39: =E39+D39 -> 203 | M39: =L39+J39 -> 430 | O39: =B39-16 -> 0
A40: 46001 | B40: 16 | C40: =J39 -> 227 | D40: 30 | E40: =L39 -> 203 | F40: 0 | G40: 0 | H40: =H39-I39 -> 4 | I40: 0 | J40: =C40+B40-D40-G40-F40 -> 213 | L40: =E40+D40 -> 233 | M40: =L40+J40 -> 446 | N40: 5 bricks with cracks | O40: =B40-16 -> 0
...

Sheet SCHEDULE OF ACTIVITIES
A1: TASK | B1: ASSIGN PER DAY | G1: TARGET | H1: REMARKS
B2: MONDAY | C2: TUESDAY | D2: WEDNESDAY | E2: THURSDAY | F2: FRIDAY
A3: 1. Printing of Bricks | B3: Niño | C3: Ross | D3: Edward | E3: Carlo | F3: Aljon | G3: 16 bricks per day
A4: 2. Wet Mixing of Clay/ Kneading of Clay | B4: Ross, Edward | C4: Edward, Carlo | D4: Carlo, Aljon | E4: Aljon, Niño | F4: Niño, Ross | G4: 200 kg of clay mix
A5: 3. Dry Grinding of Clay/ Dry Mixing of Clay | B5: Carlo, Aljon | C5: Aljon, Niño | D5: Niño, Ross | E5: Ross, Edward | F5: Edward, Carlo | G5: Taguibo clay: 134 kg Calapagan clay: 7.4 kg Sand: 7.4 kg
A8: 1. Printing of Bricks | B8: Niño / (Aljon) | C8: Ross | D8: Edward | E8: Carlo | F8: WFH | G8: 20 Bricks per day
A9: 2. Wet Mixing of Clay/ Kneading of Clay | B9: Ross, Edward / (Niño, Ross) | C9: Edward, Carlo | D9: Carlo, Aljon | E9: Aljon, Niño | F9: WFH | G9: 250 kg of clay mix
A10: 3. Dry Grinding & Mixing of Clay | B10: Carlo, Aljon (Edward, Carlo) | C10: Aljon, Niño | D10: Niño, Ross | E10: Ross, Edward | F10: WFH | G10: follow per 100 kg mix | H10: 67kg : 3.9 kg : 3.9 kg : 25.2 kg

Sheet 2026 v. INVENTORY OF BRICKS
A1: DATE | B1: Newly Printed | C1: Bricks in the Kiln for firing | D1: Reclaimed (newly Printed) | E1: Reclaimed (Air Dried) | F1: Deployed / Delivered | G1: Bricks with cracks | H1: Total Air Dried | I1: Actual Count | J1: Total Fired | K1: Overall Total | L1: Remarks/ Comment | M1: Deficit
A2: 46034 | B2: 0 | C2: 0 | D2: 0 | E2: 0 | F2: 0 | H2: 291 | J2: 262 | K2: =J2+H2 -> 553 | M2: =B2-16 -> -16
A3: 46035 | B3: 14 | C3: 29 | D3: 0 | E3: 0 | F3: 0 | H3: =H2+B3-C3-E3-D3 -> 276 | J3: =J2+C3 -> 291 | K3: =J3+H3 -> 567 | L3: with 3 cracks | M3: =B3-16 -> -2
A4: 46036 | B4: 12 | C4: 0 | D4: 0 | E4: 0 | F4: 0 | H4: =H3+B4-C4-E4-D4 -> 288 | J4: =J3+C4 -> 291 | K4: =J4+H4 -> 579 | M4: =B4-16 -> -4
A5: 46037 | B5: 10 | C5: 29 | D5: 0 | E5: 0 | F5: 0 | H5: =H4+B5-C5-E5-D5 -> 269 | J5: =J4+C5 -> 320 | K5: =J5+H5 -> 589 | L5: with 3 cracks | M5: =B5-16 -> -6
A6: 46038 | B6: 0 | C6: 0 | D6: 0 | E6: 0 | F6: 0 | H6: =H5+B6-C6-E6-D6 -> 269 | J6: =J5+C6 -> 320 | K6: =J6+H6 -> 589 | L6: no printing due to insufficient ply board for base | M6: =B6-16 -> -16
A7: 46041 | B7: 15 | C7: 0 | D7: 0 | E7: 0 | F7: 0 | H7: =H6+B7-C7-E7-D7 -> 284 | J7: =J6+C7 -> 320 | K7: =J7+H7 -> 604 | M7: =B7-16 -> -1
A8: 46042 | B8: 16 | C8: 29 | D8: 0 | E8: 0 | F8: 0 | H8: =H7+B8-C8-E8-D8 -> 271 | J8: =J7+C8 -> 349 | K8: =J8+H8 -> 620 | L8: 2 bricks with crack | M8: =B8-16 -> 0
A9: 46043 | B9: 3 | C9: 0 | D9: 0 | E9: 0 | F9: 0 | H9: =H8+B9-C9-E9-D9 -> 274 | J9: =J8+C9 -> 349 | K9: =J9+H9 -> 623 | M9: =B9-16 -> -13
A10: 46044 | B10: 3 | C10: 0 | D10: 0 | E10: 0 | F10: 0 | H10: =H9+B10-C10-E10-D10 -> 277 | J10: =J9+C10 -> 349 | K10: =J10+H10 -> 626 | M10: =B10-16 -> -13
A11: 46045 | B11: 5 | C11: 0 | D11: 0 | E11: 0 | F11: 0 | H11: =H10+B11-C11-E11-D11 -> 282 | J11: =J10+C11 -> 349 | K11: =J11+H11 -> 631 | M11: =B11-16 -> -11
A12: 46048 | B12: 13 | C12: 0 | D12: 0 | E12: 1 | F12: 0 | H12: =H11+B12-C12-E12-D12 -> 294 | J12: =J11+C12 -> 349 | K12: =J12+H12 -> 643 | M12: =B12-16 -> -3
A13: 46049 | B13: 16 | C13: 0 | D13: 0 | E13: 0 | F13: 0 | H13: =H12+B13-C13-E13-D13 -> 310 | J13: =J12+C13 -> 349 | K13: =J13+H13 -> 659 | M13: =B13-16 -> 0
A14: 46050 | B14: 10 | C14: 0 | D14: 0 | E14: 0 | F14: 0 | H14: =H13+B14-C14-E14-D14 -> 320 | J14: =J13+C14 -> 349 | K14: =J14+H14 -> 669 | M14: =B14-16 -> -6
A15: 46051 | B15: 8 | C15: 0 | D15: 0 | E15: 0 | F15: 0 | H15: =H14+B15-C15-E15-D15 -> 328 | J15: =J14+C15 -> 349 | K15: =J15+H15 -> 677 | M15: =B15-16 -> -8
A16: 46052 | B16: 0 | C16: 0 | D16: 0 | E16: 0 | F16: 0 | H16: =H15+B16-C16-E16-D16 -> 328 | J16: =J15+C16 -> 349 | K16: =J16+H16 -> 677 | M16: =B16-16 -> -16
A17: Total (Mon. of Jan) | B17: =SUM(B2:B16) -> 125 | C17: =SUM(C2:C16) -> 87 | D17: =SUM(D2:D16) -> 0 | E17: =SUM(E2:E16) -> 1 | F17: =SUM(F2:F16) -> 0 | H17: =H16 -> 328 | J17: =J16 -> 349 | K17: =J17+H17 -> 677 | M17: =B17-16 -> 109
A18: 46055 | B18: 12 | C18: 0 | D18: 0 | E18: 0 | F18: 0 | H18: =H16+B18-C18-E18-D18 -> 340 | J18: =J17+C18 -> 349 | K18: =J18+H18 -> 689 | M18: =B18-16 -> -4
A19: 46056 | B19: 15 | C19: 0 | D19: 0 | E19: 0 | F19: 0 | H19: =H18+B19-C19-E19-D19 -> 355 | J19: =J18+C19 -> 349 | K19: =J19+H19 -> 704 | M19: =B19-16 -> -1
A20: 46057 | B20: 15 | C20: 0 | D20: 0 | E20: 0 | F20: 0 | H20: =H19+B20-C20-E20-D20 -> 370 | J20: =J19+C20 -> 349 | K20: =J20+H20 -> 719 | M20: =B20-16 -> -1
A21: 46058 | B21: 4 | C21: 0 | D21: 0 | E21: 0 | F21: 0 | H21: =H20+B21-C21-E21-D21 -> 374 | J21: =J20+C21 -> 349 | K21: =J21+H21 -> 723 | L21: work suspended due to weather | M21: =B21-16 -> -12
A22: 46059 | B22: 0 | C22: 0 | D22: 0 | E22: 0 | F22: 0 | H22: =H21+B22-C22-E22-D22 -> 374 | J22: =J21+C22 -> 349 | K22: =J22+H22 -> 723 | L22: work suspended due to weather | M22: =B22-16 -> -16
A23: Weekly Total Output | B23: =SUM(B18:B22) -> 46 | C23: =SUM(C18:C22) -> 0 | D23: =SUM(D18:D22) -> 0 | E23: =SUM(E18:E22) -> 0 | F23: =SUM(F18:F22) -> 0 | H23: =H22 -> 374 | J23: =J22 -> 349 | K23: =J23+H23 -> 723 | L23: deficit due to suspension of work: 28 deficit during WD: 6 | M23: =B23-16 -> 30
A24: 46062 | B24: 19 | C24: 0 | D24: 0 | E24: 0 | F24: 0 | H24: =H22+B24-C24-E24-D24 -> 393 | J24: =C24+J23 -> 349 | K24: =J24+H24 -> 742 | M24: =B24-16 -> 3
A25: 46063 | B25: 24 | C25: 0 | D25: 0 | E25: 0 | F25: 0 | H25: =H24+B25-C25-E25-D25 -> 417 | J25: =C25+J24 -> 349 | K25: =J25+H25 -> 766 | M25: =B25-16 -> 8
A26: 46064 | B26: 23 | C26: 0 | D26: 1 | E26: 0 | F26: 0 | H26: =H25+B26-C26-E26-D26 -> 439 | J26: =C26+J25 -> 349 | K26: =J26+H26 -> 788 | L26: recliamed brick was due to the pin issue . | M26: =B26-16 -> 7
A27: 46065 | B27: 15 | C27: 0 | D27: 0 | E27: 0 | F27: 0 | H27: =H26+B27-C27-E27-D27 -> 454 | J27: =C27+J26 -> 349 | K27: =J27+H27 -> 803 | M27: =B27-16 -> -1
A28: 46066 | B28: 14 | C28: 29 | D28: 0 | E28: 0 | F28: 0 | H28: =H27+B28-C28-E28-D28 -> 439 | J28: =C28+J27 -> 378 | K28: =J28+H28 -> 817 | L28: with only 3 minor cracks( hairline cracks) | M28: =B28-16 -> -2
A29: Weekly Total Output | B29: =SUM(B24:B28) -> 95 | C29: =SUM(C24:C28) -> 29 | D29: =SUM(D24:D28) -> 1 | E29: =SUM(E24:E28) -> 0 | F29: =SUM(F24:F28) -> 0 | H29: =H28 -> 439 | J29: =J28 -> 378 | K29: =J29+H29 -> 817 | L29: excess: 15 units of bricks | M29: =B29-16 -> 79
A30: 46069 | B30: 14 | C30: 0 | D30: 0 | E30: 0 | F30: 0 | H30: =H28+B30-C30-E30-D30 -> 453 | J30: =J29+C30 -> 378 | K30: =J30+H30 -> 831 | M30: =B30-16 -> -2
A31: 46070 | B31: 0 | C31: 0 | D31: 0 | E31: 0 | F31: 0 | H31: =H30+B31-C31-E31-D31 -> 453 | J31: =J30+C31 -> 378 | K31: =J31+H31 -> 831 | L31: HOLIDAY-CHINESE NEW YEAR | M31: =B31-16 -> -16
A32: 46071 | B32: 14 | C32: 29 | D32: 0 | E32: 0 | F32: 0 | H32: =H31+B32-C32-E32-D32 -> 438 | J32: =J31+C32 -> 407 | K32: =J32+H32 -> 845 | L32: with 1 major cracks and 5 hairline cracks. | M32: =B32-16 -> -2
A33: 46072 | B33: 10 | C33: 0 | D33: 0 | E33: 0 | F33: 0 | H33: =H32+B33-C33-E33-D33 -> 448 | J33: =J32+C33 -> 407 | K33: =J33+H33 -> 855 | L33: WORK SUSPENDED DUE TO HEAVY RAIN | M33: =A33-16 -> 46056
A34: 46073 | B34: 0 | C34: 0 | D34: 0 | E34: 0 | F34: 0 | H34: =H33+B34-C34-E34-D34 -> 448 | J34: =J33+C34 -> 407 | K34: =J34+H34 -> 855 | L34: WORK SUSPENDED DUE TO HEAVY RAIN | M34: =A34-16 -> 46057
A35: WEEKLY TOTAL OUTPUT | B35: =SUM(B30:B34) -> 38 | C35: =SUM(C30:C34) -> 29 | D35: =SUM(D30:D34) -> 0 | E35: =SUM(E30:E34) -> 0 | F35: 0 | H35: =H34 -> 448 | J35: =J34 -> 407 | K35: =J35+H35 -> 855 | L35: deficit due to suspension of work (SoW): 38 deficit during Working Days (WD) : 4 | M35: =A35-16 -> #VALUE!
A36: 46076 | B36: 15 | C36: 29 | D36: 3 | E36: 0 | F36: 0 | H36: =H34+B36-C36-E36 -> 434 | J36: =J35+C36-F36 -> 436 | K36: =J36+H36 -> 870 | L36: 2 with major cracks; 1 with hairline cracks. | M36: =B36-16 -> -1
A37: 46077 | B37: 18 | C37: 0 | D37: 0 | E37: 0 | F37: 0 | H37: =H36+B37-C37-E37-D37 -> 452 | J37: =J36+C37-F37 -> 436 | K37: =J37+H37 -> 888 | M37: =B37-16 -> 2
A38: 46078 | B38: 24 | C38: 0 | D38: 0 | E38: 0 | F38: 62 | H38: =H37+B38-C38-E38-D38 -> 476 | J38: =J37+C38-F38 -> 374 | K38: =J38+H38 -> 850 | L38: HOLIDAY- NINOY AQUINO ANI./ WFH SET-UP 62 bricks shipped to the cebu | M38: =B38-16 -> 8
A39: 46079 | B39: 8 | C39: 0 | D39: 0 | E39: 0 | F39: 0 | H39: =H38+B39-C39-E39-D39 -> 484 | J39: =J38+C39-F39 -> 374 | K39: =J39+H39 -> 858 | L39: brown out occured on afternoon 4pm | M39: =B39-16 -> -8
A40: 46080 | B40: 19 | C40: 29 | D40: 0 | E40: 0 | F40: 0 | H40: =H39+B40-C40-E40-D40 -> 474 | J40: =J39+C40-F40 -> 403 | K40: =J40+H40 -> 877 | L40: 4 with cracks | M40: =B40-16 -> 3
...

Sheet 2026 v. INVENTORY FOR CLAY MIXT
A1: DATE | B1: Available Taguibo Clay (No. of Bags) | C1: Available Calapagan Clay (kg) | D1: Available Fine Sand (kg) | E1: Soaked Clay for the Day (in kg) | F1: Total Soaked Clay Mixture, (in kg) | G1: Prepared RTP Mix for the Day (in kg) | H1: Reclaimed RTP Mix, (in kg) | I1: Total Available + Remaining RTP Mix (in kg) | J1: USED RTP Mix, (in kg) | K1: Total Remaing RTP Mix (in kg) | L1: TARGET SOAKED CLAY MIXTURE (in kg) | M1: TARGET PREPARED CLAY MIXTURE (in kg) | N1: REMARKS
A2: 46055 | E2: 200 | F2: 100 | G2: 180 | I2: =H2+G2 -> 180 | J2: =8*'2026 v. INVENTORY OF BRICKS'!B18 -> 96 | K2: =I2-J2 -> 84
A3: 46056 | E3: 100 | F3: =F2+E3-G3 -> 0 | G3: 200 | H3: 0 | I3: =H3+G3+K2 -> 284 | J3: =8*'2026 v. INVENTORY OF BRICKS'!B19 -> 120 | K3: =I3-J3 -> 164
A4: 46057 | E4: 100 | F4: =F3+E4-G4 -> 0 | G4: 100 | H4: 0 | I4: =H4+G4+K3 -> 264 | J4: =8*'2026 v. INVENTORY OF BRICKS'!B20 -> 120 | K4: =I4-J4 -> 144
A5: 46058 | E5: 0 | F5: =F4+E5-G5 -> 0 | G5: 0 | H5: 0 | I5: =H5+G5+K4 -> 144 | J5: =8*'2026 v. INVENTORY OF BRICKS'!B21 -> 32 | K5: =I5-J5 -> 112 | N5: regular working days suspended due to bad weather.
A6: 46059 | E6: 0 | F6: =F5+E6-G6 -> 0 | G6: 0 | H6: 0 | I6: =H6+G6+K5 -> 112 | J6: =8*'2026 v. INVENTORY OF BRICKS'!B22 -> 0 | K6: =I6-J6 -> 112 | N6: regular working days suspended due to bad weather.
A7: 46062 | E7: 200 | F7: =F6+E7-G7 -> 100 | G7: 100 | H7: 0 | I7: =H7+G7+K6 -> 212 | J7: =8*'2026 v. INVENTORY OF BRICKS'!B24 -> 152 | K7: =I7-J7 -> 60
A8: 46063 | E8: 200 | F8: =F7+E8-G8 -> 100 | G8: 200 | H8: 0 | I8: =H8+G8+K7 -> 260 | J8: =8*'2026 v. INVENTORY OF BRICKS'!B25 -> 192 | K8: =I8-J8 -> 68
A9: 46064 | E9: 200 | F9: =F8+E9-G9 -> 100 | G9: 200 | H9: 0 | I9: =H9+G9+K8 -> 268 | J9: =8*'2026 v. INVENTORY OF BRICKS'!B26 -> 184 | K9: =I9-J9 -> 84
A10: 46065 | E10: 108 | F10: =F9+E10-G10 -> 108 | G10: 100 | H10: 0 | I10: =H10+G10+K9 -> 184 | J10: =8*'2026 v. INVENTORY OF BRICKS'!B27 -> 120 | K10: =I10-J10 -> 64
A11: 46066 | E11: 200 | F11: =F10+E11-G11 -> 208 | G11: 100 | H11: 8 | I11: =H11+G11+K10 -> 172 | J11: =8*'2026 v. INVENTORY OF BRICKS'!B28 -> 112 | K11: =I11-J11 -> 60
A12: 46069 | E12: 100 | F12: =F11+E12-G12 -> 108 | G12: 200 | H12: 0 | I12: =H12+G12+K11 -> 260 | J12: =8*'2026 v. INVENTORY OF BRICKS'!B30 -> 112 | K12: =I12-J12 -> 148
A13: 46070 | E13: 0 | F13: =F12+E13-G13 -> 108 | G13: 0 | H13: 0 | I13: =H13+G13+K12 -> 148 | J13: =8*'2026 v. INVENTORY OF BRICKS'!B31 -> 0 | K13: =I13-J13 -> 148 | N13: Holiday
A14: 46071 | E14: 100 | F14: =F13+E14-G14 -> 208 | G14: 0 | H14: 0 | I14: =H14+G14+K13 -> 148 | J14: =8*'2026 v. INVENTORY OF BRICKS'!B32 -> 112 | K14: =I14-J14 -> 36
A15: 46072 | E15: 0 | F15: =F14+E15-G15 -> 8 | G15: 200 | H15: 0 | I15: =H15+G15+K14 -> 236 | J15: =8*'2026 v. INVENTORY OF BRICKS'!B33 -> 80 | K15: =I15-J15 -> 156 | N15: regular working days suspended due to bad weather.(half day)
A16: 46073 | E16: 0 | F16: =F15+E16-G16 -> 8 | G16: 0 | H16: 0 | I16: =H16+G16+K15 -> 156 | J16: =8*'2026 v. INVENTORY OF BRICKS'!B34 -> 0 | K16: =I16-J16 -> 156 | N16: regular working days suspended due to bad weather.
A17: 46076 | E17: 100 | F17: =F16+E17-G17 -> 8 | G17: 100 | H17: 0 | I17: =H17+G17+K16 -> 256 | J17: =8*'2026 v. INVENTORY OF BRICKS'!B36 -> 120 | K17: =I17-J17 -> 136
A18: 46077 | E18: 200 | F18: =F17+E18-G18 -> 108 | G18: 100 | H18: 0 | I18: =H18+G18+K17 -> 236 | J18: =8*'2026 v. INVENTORY OF BRICKS'!B37 -> 144 | K18: =I18-J18 -> 92
A19: 46078 | E19: 100 | F19: =F18+E19-G19 -> 8 | G19: 200 | H19: 0 | I19: =H19+G19+K18 -> 292 | J19: =8*'2026 v. INVENTORY OF BRICKS'!B38 -> 192 | K19: =I19-J19 -> 100 | N19: Holiday - Ninoy Aquino day
A20: 46079 | E20: 300 | F20: =F19+E20-G20 -> 208 | G20: 100 | I20: =H20+G20+K19 -> 200 | J20: =8*'2026 v. INVENTORY OF BRICKS'!B39 -> 64 | K20: =I20-J20 -> 136
A21: 46080 | E21: 200 | F21: =F20+E21-G21 -> 208 | G21: 200 | I21: =H21+G21+K20 -> 336 | J21: =8*'2026 v. INVENTORY OF BRICKS'!B40 -> 152 | K21: =I21-J21 -> 184
A22: TOTAL | E22: =SUM(E2:E21) -> 2408 | G22: =SUM(G2:G21) -> 2280 | H22: =SUM(H2:H21) -> 8 | I22: =H22+G22+K21 -> 2472 | J22: =SUM(J2:J21) -> 2104 | K22: =I22-J22 -> 368
A23: 46083 | E23: 0 | F23: =F21+E23-G23 -> 0 | G23: 208 | H23: 0 | I23: =H23+G23+K21 -> 392 | J23: =10*'2026 v. INVENTORY OF BRICKS'!B43 -> 170 | K23: =I23-J23 -> 222 | N23: no more supply; vehicle used for hauling incur damage during transport from Taguibo to Marfori.
A24: 46084 | E24: 0 | F24: 0 | G24: 0 | H24: 0 | I24: =H24+G24+K23 -> 222 | J24: =8*'2026 v. INVENTORY OF BRICKS'!B44 -> 160 | K24: =I24-J24 -> 62
A25: 46085 | E25: 200 | F25: =F24+E25-G25 -> 200 | G25: 0 | H25: 0 | I25: =H25+G25+K24 -> 62 | J25: =8*'2026 v. INVENTORY OF BRICKS'!B45 -> 0 | K25: =I25-J25 -> 62
A26: 46086 | E26: 300 | F26: =F25+E26-G26 -> 400 | G26: 100 | H26: 0 | I26: =H26+G26+K25 -> 162 | J26: =8*'2026 v. INVENTORY OF BRICKS'!B46 -> 160 | K26: =I26-J26 -> 2
A27: 46087 | E27: 0 | F27: =F26+E27-G27 -> 200 | G27: 200 | H27: 0 | I27: =H27+G27+K26 -> 202 | J27: =8*'2026 v. INVENTORY OF BRICKS'!B47 -> 64 | K27: =I27-J27 -> 138
A28: 46090 | E28: 300 | F28: =F27+E28-G28 -> 500 | G28: 0 | H28: 0 | I28: 172 | J28: 172 | K28: =I28-J28 -> 0 | N28: prio the printing of the 183 mini bricks
A29: 46091 | E29: 300 | F29: =F28+E29-G29 -> 500 | G29: 300 | H29: 0 | I29: =H29+G29+K28 -> 300 | J29: =10*'2026 v. INVENTORY OF BRICKS'!B50 -> 190 | K29: =I29-J29-100 -> 10 | N29: 100 kg use to print mini bricks
A30: 46092 | E30: 0 | F30: =F29+E30-G30 -> 200 | G30: 300 | H30: 0 | I30: =H30+G30+K29 -> 310 | J30: =10*'2026 v. INVENTORY OF BRICKS'!B51 -> 190 | K30: =I30-J30 -> 120
A31: 46093 | E31: 100 | F31: =F30+E31-G31 -> 100 | G31: 200 | H31: 0 | I31: =H31+G31+K30 -> 320 | J31: =10*'2026 v. INVENTORY OF BRICKS'!B52 -> 170 | K31: =I31-J31 -> 150
A32: 46094 | E32: 0 | F32: =F31+E32-G32 -> 100 | G32: 0 | H32: 0 | I32: =H32+G32+K31 -> 150 | J32: =10*'2026 v. INVENTORY OF BRICKS'!B53 -> 0 | K32: =I32-J32 -> 150 | N32: Work-From-Home (WFH)
A33: 46097 | E33: 0 | F33: =F32+E33-G33 -> 0 | G33: 100 | H33: 0 | I33: =H33+G33+K32 -> 250 | J33: =10*'2026 v. INVENTORY OF BRICKS'!B56 -> 190 | K33: =I33-J33 -> 60 | N33: clay still wet
A34: 46098 | E34: 100 | F34: =F33+E34-G34 -> 100 | G34: 0 | H34: 0 | I34: =H34+G34+K33 -> 60 | J34: =10*'2026 v. INVENTORY OF BRICKS'!B57 -> 20 | K34: =I34-J34 -> 40
A35: 46099 | E35: 0 | F35: =F33+E35-G35 -> 0 | G35: 0 | H35: 0 | I35: =H35+G35+K34 -> 40 | J35: =10*'2026 v. INVENTORY OF BRICKS'!B81 -> 0 | K35: =I35-J35 -> 40
A36: 46100 | E36: 100 | F36: =F35+E36-G36 -> 100 | G36: 0 | H36: 0 | I36: =H36+G36+K35 -> 40 | J36: =10*'2026 v. INVENTORY OF BRICKS'!B82 -> 0 | K36: =I36-J36 -> 40
A37: 46104 | E37: 200 | F37: =F36+E37-G37 -> 200 | G37: 100 | H37: 0 | I37: =H37+G37+K36 -> 140 | J37: =12*'2026 v. INVENTORY OF BRICKS'!B61 -> 96 | K37: =I37-J37 -> 44
A38: 46105 | E38: 300 | F38: =F37+E38-G38 -> 300 | G38: 200 | H38: 0 | I38: =H38+G38+K37 -> 244 | J38: =12*'2026 v. INVENTORY OF BRICKS'!B62 -> 192 | K38: =I38-J38 -> 52
A39: 46106 | E39: 200 | F39: =F38+E39-G39 -> 200 | G39: 300 | H39: 0 | I39: =H39+G39+K38 -> 352 | J39: =12*'2026 v. INVENTORY OF BRICKS'!B63 -> 216 | K39: =I39-J39 -> 136
A40: 46107 | E40: 200 | F40: =F39+E40-G40 -> 200 | G40: 200 | H40: 0 | I40: =H40+G40+K39 -> 336 | J40: =12*'2026 v. INVENTORY OF BRICKS'!B64 -> 288 | K40: =I40-J40 -> 48
...
